Workbook

Sheet Synthèse
A1: Ads diffusées & CTR — septembre 2026
A2: Annonces directes Lemrock Media Network, 1–30 septembre 2026 (UTC). CTR = clics / impressions.
A4: Client | B4: Statut | C4: Nb ads diffusées | D4: Impressions | E4: Clics | F4: CTR | G4: Remarque
A5: Clients Live
A6: Boulanger | B6: Live | C6: =COUNTIFS('Détail par ad'!$A$2:$A$2174,A6) | D6: =SUMIFS('Détail par ad'!$H$2:$H$2174,'Détail par ad'!$A$2:$A$2174,A6) | E6: =SUMIFS('Détail par ad'!$I$2:$I$2174,'Détail par ad'!$A$2:$A$2174,A6) | F6: =IF(D6=0,"—",E6/D6)
A7: Cdiscount Voyages | B7: Live | C7: =COUNTIFS('Détail par ad'!$A$2:$A$2174,A7) | D7: =SUMIFS('Détail par ad'!$H$2:$H$2174,'Détail par ad'!$A$2:$A$2174,A7) | E7: =SUMIFS('Détail par ad'!$I$2:$I$2174,'Détail par ad'!$A$2:$A$2174,A7) | F7: =IF(D7=0,"—",E7/D7)
A8: Monoprix | B8: Live | C8: =COUNTIFS('Détail par ad'!$A$2:$A$2174,A8) | D8: =SUMIFS('Détail par ad'!$H$2:$H$2174,'Détail par ad'!$A$2:$A$2174,A8) | E8: =SUMIFS('Détail par ad'!$I$2:$I$2174,'Détail par ad'!$A$2:$A$2174,A8) | F8: =IF(D8=0,"—",E8/D8)
A9: Cdiscount Mobile | B9: Live | C9: =COUNTIFS('Détail par ad'!$A$2:$A$2174,A9) | D9: =SUMIFS('Détail par ad'!$H$2:$H$2174,'Détail par ad'!$A$2:$A$2174,A9) | E9: =SUMIFS('Détail par ad'!$I$2:$I$2174,'Détail par ad'!$A$2:$A$2174,A9) | F9: =IF(D9=0,"—",E9/D9)
A10: Qonto | B10: Live | C10: =COUNTIFS('Détail par ad'!$A$2:$A$2174,A10) | D10: =SUMIFS('Détail par ad'!$H$2:$H$2174,'Détail par ad'!$A$2:$A$2174,A10) | E10: =SUMIFS('Détail par ad'!$I$2:$I$2174,'Détail par ad'!$A$2:$A$2174,A10) | F10: =IF(D10=0,"—",E10/D10)
A11: Basket4ballers | B11: Live | C11: =COUNTIFS('Détail par ad'!$A$2:$A$2174,A11) | D11: =SUMIFS('Détail par ad'!$H$2:$H$2174,'Détail par ad'!$A$2:$A$2174,A11) | E11: =SUMIFS('Détail par ad'!$I$2:$I$2174,'Détail par ad'!$A$2:$A$2174,A11) | F11: =IF(D11=0,"—",E11/D11)
A12: FidMe | B12: Live | C12: =COUNTIFS('Détail par ad'!$A$2:$A$2174,A12) | D12: =SUMIFS('Détail par ad'!$H$2:$H$2174,'Détail par ad'!$A$2:$A$2174,A12) | E12: =SUMIFS('Détail par ad'!$I$2:$I$2174,'Détail par ad'!$A$2:$A$2174,A12) | F12: =IF(D12=0,"—",E12/D12)
A13: Pour de Bon | B13: Live | C13: =COUNTIFS('Détail par ad'!$A$2:$A$2174,A13) | D13: =SUMIFS('Détail par ad'!$H$2:$H$2174,'Détail par ad'!$A$2:$A$2174,A13) | E13: =SUMIFS('Détail par ad'!$I$2:$I$2174,'Détail par ad'!$A$2:$A$2174,A13) | F13: =IF(D13=0,"—",E13/D13)
A14: PV | B14: Live | C14: =COUNTIFS('Détail par ad'!$A$2:$A$2174,A14) | D14: =SUMIFS('Détail par ad'!$H$2:$H$2174,'Détail par ad'!$A$2:$A$2174,A14) | E14: =SUMIFS('Détail par ad'!$I$2:$I$2174,'Détail par ad'!$A$2:$A$2174,A14) | F14: =IF(D14=0,"—",E14/D14)
A15: Allo Pneus | B15: Live | C15: =COUNTIFS('Détail par ad'!$A$2:$A$2174,A15) | D15: =SUMIFS('Détail par ad'!$H$2:$H$2174,'Détail par ad'!$A$2:$A$2174,A15) | E15: =SUMIFS('Détail par ad'!$I$2:$I$2174,'Détail par ad'!$A$2:$A$2174,A15) | F15: =IF(D15=0,"—",E15/D15)
A16: Marshall | B16: Live | C16: =COUNTIFS('Détail par ad'!$A$2:$A$2174,A16) | D16: =SUMIFS('Détail par ad'!$H$2:$H$2174,'Détail par ad'!$A$2:$A$2174,A16) | E16: =SUMIFS('Détail par ad'!$I$2:$I$2174,'Détail par ad'!$A$2:$A$2174,A16) | F16: =IF(D16=0,"—",E16/D16)
A17: Dorel | B17: Live | C17: =COUNTIFS('Détail par ad'!$A$2:$A$2174,A17) | D17: =SUMIFS('Détail par ad'!$H$2:$H$2174,'Détail par ad'!$A$2:$A$2174,A17) | E17: =SUMIFS('Détail par ad'!$I$2:$I$2174,'Détail par ad'!$A$2:$A$2174,A17) | F17: =IF(D17=0,"—",E17/D17)
... A22: Archipel Kombucha | B22: Live | C22: =COUNTIFS('Détail par ad'!$A$2:$A$2174,A22) | D22: =SUMIFS('Détail par ad'!$H$2:$H$2174,'Détail par ad'!$A$2:$A$2174,A22) | E22: =SUMIFS('Détail par ad'!$I$2:$I$2174,'Détail par ad'!$A$2:$A$2174,A22) | F22: =IF(D22=0,"—",E22/D22)
A23: SNCF | B23: Live | C23: =COUNTIFS('Détail par ad'!$A$2:$A$2174,A23) | D23: =SUMIFS('Détail par ad'!$H$2:$H$2174,'Détail par ad'!$A$2:$A$2174,A23) | E23: =SUMIFS('Détail par ad'!$I$2:$I$2174,'Détail par ad'!$A$2:$A$2174,A23) | F23: =IF(D23=0,"—",E23/D23) | G23: Lancé le 30/09 : 1 seul jour de diffusion en septembre
A24: Elhée | B24: Live | C24: =COUNTIFS('Détail par ad'!$A$2:$A$2174,A24) | D24: =SUMIFS('Détail par ad'!$H$2:$H$2174,'Détail par ad'!$A$2:$A$2174,A24) | E24: =SUMIFS('Détail par ad'!$I$2:$I$2174,'Détail par ad'!$A$2:$A$2174,A24) | F24: =IF(D24=0,"—",E24/D24) | G24: Lancé le 07/10 : aucune diffusion en septembre
A25: Mabex | B25: Live | C25: =COUNTIFS('Détail par ad'!$A$2:$A$2174,A25) | D25: =SUMIFS('Détail par ad'!$H$2:$H$2174,'Détail par ad'!$A$2:$A$2174,A25) | E25: =SUMIFS('Détail par ad'!$I$2:$I$2174,'Détail par ad'!$A$2:$A$2174,A25) | F25: =IF(D25=0,"—",E25/D25) | G25: Aucune diffusion trouvée en septembre
A26: Sous-total | C26: =SUM(C6:C25) | D26: =SUM(D6:D25) | E26: =SUM(E6:E25) | F26: =IF(D26=0,"—",E26/D26)
A28: Clients en fin de campagne (diffusés en septembre)
A29: Ryobi | B29: Terminé | C29: =COUNTIFS('Détail par ad'!$A$2:$A$2174,A29) | D29: =SUMIFS('Détail par ad'!$H$2:$H$2174,'Détail par ad'!$A$2:$A$2174,A29) | E29: =SUMIFS('Détail par ad'!$I$2:$I$2174,'Détail par ad'!$A$2:$A$2174,A29) | F29: =IF(D29=0,"—",E29/D29)
A30: Iopole | B30: Terminé | C30: =COUNTIFS('Détail par ad'!$A$2:$A$2174,A30) | D30: =SUMIFS('Détail par ad'!$H$2:$H$2174,'Détail par ad'!$A$2:$A$2174,A30) | E30: =SUMIFS('Détail par ad'!$I$2:$I$2174,'Détail par ad'!$A$2:$A$2174,A30) | F30: =IF(D30=0,"—",E30/D30)
A31: La redoute | B31: Terminé | C31: =COUNTIFS('Détail par ad'!$A$2:$A$2174,A31) | D31: =SUMIFS('Détail par ad'!$H$2:$H$2174,'Détail par ad'!$A$2:$A$2174,A31) | E31: =SUMIFS('Détail par ad'!$I$2:$I$2174,'Détail par ad'!$A$2:$A$2174,A31) | F31: =IF(D31=0,"—",E31/D31)
A32: Bayard Jeunesse | B32: Terminé | C32: =COUNTIFS('Détail par ad'!$A$2:$A$2174,A32) | D32: =SUMIFS('Détail par ad'!$H$2:$H$2174,'Détail par ad'!$A$2:$A$2174,A32) | E32: =SUMIFS('Détail par ad'!$I$2:$I$2174,'Détail par ad'!$A$2:$A$2174,A32) | F32: =IF(D32=0,"—",E32/D32)
A33: Franklin Pet Food | B33: Terminé | C33: =COUNTIFS('Détail par ad'!$A$2:$A$2174,A33) | D33: =SUMIFS('Détail par ad'!$H$2:$H$2174,'Détail par ad'!$A$2:$A$2174,A33) | E33: =SUMIFS('Détail par ad'!$I$2:$I$2174,'Détail par ad'!$A$2:$A$2174,A33) | F33: =IF(D33=0,"—",E33/D33)
A34: 1001 Pneus | B34: Terminé | C34: =COUNTIFS('Détail par ad'!$A$2:$A$2174,A34) | D34: =SUMIFS('Détail par ad'!$H$2:$H$2174,'Détail par ad'!$A$2:$A$2174,A34) | E34: =SUMIFS('Détail par ad'!$I$2:$I$2174,'Détail par ad'!$A$2:$A$2174,A34) | F34: =IF(D34=0,"—",E34/D34)
A35: La marque en moins | B35: Terminé | C35: =COUNTIFS('Détail par ad'!$A$2:$A$2174,A35) | D35: =SUMIFS('Détail par ad'!$H$2:$H$2174,'Détail par ad'!$A$2:$A$2174,A35) | E35: =SUMIFS('Détail par ad'!$I$2:$I$2174,'Détail par ad'!$A$2:$A$2174,A35) | F35: =IF(D35=0,"—",E35/D35)
A36: Ultra Premium Direct | B36: Terminé | C36: =COUNTIFS('Détail par ad'!$A$2:$A$2174,A36) | D36: =SUMIFS('Détail par ad'!$H$2:$H$2174,'Détail par ad'!$A$2:$A$2174,A36) | E36: =SUMIFS('Détail par ad'!$I$2:$I$2174,'Détail par ad'!$A$2:$A$2174,A36) | F36: =IF(D36=0,"—",E36/D36)
A37: Sous-total | C37: =SUM(C29:C36) | D37: =SUM(D29:D36) | E37: =SUM(E29:E36) | F37: =IF(D37=0,"—",E37/D37)
A39: Hors fichier de suivi
A40: MINI | B40: Hors fichier de suivi | C40: =COUNTIFS('Détail par ad'!$A$2:$A$2174,A40) | D40: =SUMIFS('Détail par ad'!$H$2:$H$2174,'Détail par ad'!$A$2:$A$2174,A40) | E40: =SUMIFS('Détail par ad'!$I$2:$I$2174,'Détail par ad'!$A$2:$A$2174,A40) | F40: =IF(D40=0,"—",E40/D40) | G40: Annonceur absent du fichier de suivi
A41: Comptoir des Pros | B41: Hors fichier de suivi | C41: =COUNTIFS('Détail par ad'!$A$2:$A$2174,A41) | D41: =SUMIFS('Détail par ad'!$H$2:$H$2174,'Détail par ad'!$A$2:$A$2174,A41) | E41: =SUMIFS('Détail par ad'!$I$2:$I$2174,'Détail par ad'!$A$2:$A$2174,A41) | F41: =IF(D41=0,"—",E41/D41) | G41: Annonceur absent du fichier de suivi
A42: Sous-total | C42: =SUM(C40:C41) | D42: =SUM(D40:D41) | E42: =SUM(E40:E41) | F42: =IF(D42=0,"—",E42/D42)
A44: TOTAL | C44: =C26+C37+C42 | D44: =D26+D37+D42 | E44: =E26+E37+E42 | F44: =IF(D44=0,"—",E44/D44)

Sheet Détail par ad
A1: Client | B1: Statut | C1: Campagne | D1: Groupe d'annonces | E1: Titre de l'ad | F1: Description | G1: URL de destination | H1: Impressions | I1: Clics | J1: CTR
A2: Boulanger | B2: Live | C2: Boulanger | D2: Enceintes et barres de son | E2: Barre de son BOSE TV Speaker | F2: Une barre compacte qui rend les dialogues de vos films plus clairs, branchée d’un seul câble sous la télé. Livraison offerte et garantie 2 ans chez Boulanger. | G2: https://www.boulanger.com/ref/1145344?at_medium=gea&at_campaign=lemrock | H2: 52227 | I2: 147 | J2: =IF(H2=0,0,I2/H2)
A3: Boulanger | B3: Live | C3: Boulanger | D3: Smartphones et accessoires | E3: Smartphone SAMSUNG Galaxy S24 Ultra Gris | F3: Bienvenue dans la nouvelle ère de l'Intelligence Artificielle mobile. Entre vos mains, le Galaxy S24 Ultra vous ouvre de nouveaux horizons. Productifs d'abord, avec des | G3: https://www.boulanger.com/ref/1200027?at_medium=gea&at_campaign=lemrock | H3: 42500 | I3: 217 | J3: =IF(H3=0,0,I3/H3)
A4: Boulanger | B4: Live | C4: Boulanger | D4: Consoles de jeux | E4: Console Portable ASUS Rog Xbox Ally | F4: Console portable Asus qui fait tourner vos jeux Xbox et PC partout, sans télé ; reprise de votre ancienne console et retrait en une heure en magasin Boulanger. | G4: https://www.boulanger.com/ref/1224182?at_medium=gea&at_campaign=lemrock | H4: 40605 | I4: 1390 | J4: =IF(H4=0,0,I4/H4)
A5: Boulanger | B5: Live | C5: Boulanger | D5: Consoles de jeux | E5: Console NINTENDO Switch 2 | F5: La nouvelle console Nintendo, jouable sur la TV ou en déplacement, pour toute la famille ; retirez la Switch 2 en une heure dans votre magasin Boulanger, garantie 2 ans. | G5: https://www.boulanger.com/ref/1220464?at_medium=gea&at_campaign=lemrock | H5: 39174 | I5: 346 | J5: =IF(H5=0,0,I5/H5)
A6: Boulanger | B6: Live | C6: Boulanger | D6: Consumer Electronics | E6: Informatique, son et téléphonie prix bas | Boulanger | F6: Chargeur secteur Watt and Co Uni. 3000 mAh : une solution de charge universelle, compatible avec la plupart de vos appareils, à retrouver chez Boulanger. | G6: https://www.boulanger.com/ref/151244?at_medium=gea&at_campaign=lemrock | H6: 38962 | I6: 373 | J6: =IF(H6=0,0,I6/H6)
A7: Boulanger | B7: Live | C7: Boulanger | D7: Electronics and Appliance Stores | E7: High-tech et électroménager au meilleur prix | Boulanger | F7: Piano de cuisson mixte Falcon Delux 110 noir et laiton : le savoir-faire britannique, un design de tradition et des performances de cuisine pro. | G7: https://www.boulanger.com/ref/777415?at_medium=gea&at_campaign=lemrock | H7: 29388 | I7: 186 | J7: =IF(H7=0,0,I7/H7)
A8: Boulanger | B8: Live | C8: Boulanger | D8: Informatique | E8: Clavier+Souris LOGITECH MK330 | F8: Logitech Wireless Combo MK330. L'ensemble clavier/souris qui combine divertissement et portabilité. Les 11 touches de raccourci et les 12 touches F programmables vous permettent | G8: https://www.boulanger.com/ref/137017?at_medium=gea&at_campaign=lemrock | H8: 28415 | I8: 210 | J8: =IF(H8=0,0,I8/H8)
A9: Boulanger | B9: Live | C9: Boulanger | D9: Informatique | E9: Ecran ASUS ZENSCREEN MB16AWP Portable 16 | F9: Avec sa batterie et son Wi-Fi intégrés, l'écran ASUS Zenscreen MB16AWP saura séduire les travailleurs qui se déplacent régulièrement. Un ordinateur léger, élégant et portatif | G9: https://www.boulanger.com/ref/1179218?at_medium=gea&at_campaign=lemrock | H9: 28172 | I9: 157 | J9: =IF(H9=0,0,I9/H9)
A10: Boulanger | B10: Live | C10: Boulanger | D10: GPS auto et vélo | E10: GPS vélo GARMIN Edge Explore 2 - support potence | F10: Compteur GPS Garmin avec support de potence fourni, pour suivre votre itinéraire et vos sorties vélo sans sortir le téléphone ; livraison offerte et garantie 2 ans. | G10: https://www.boulanger.com/ref/1205648?at_medium=gea&at_campaign=lemrock | H10: 26642 | I10: 125 | J10: =IF(H10=0,0,I10/H10)
A11: Boulanger | B11: Live | C11: Boulanger | D11: GPS auto et vélo | E11: GPS TOMTOM GO CLASSIC 5'' EU nouvelle génération | F11: Écran 5 pouces et cartes d’Europe mises à jour pour rouler l’esprit tranquille, sans sortir votre téléphone. Livraison offerte et garantie 2 ans chez Boulanger. | G11: https://www.boulanger.com/ref/1213099?at_medium=gea&at_campaign=lemrock | H11: 26461 | I11: 70 | J11: =IF(H11=0,0,I11/H11)
A12: Boulanger | B12: Live | C12: Boulanger | D12: Enceintes et audio | E12: Enc. YAMAHA MusicCast 20 blanc | F12: Libérez-vous de tout câble et profitez de vos musiques préférez où que vous soyez avec l'enceinte connecté Yamaha MusicCast 20. Avec ses deux haut-parleurs deux voies avec un | G12: https://www.boulanger.com/ref/1112317?at_medium=gea&at_campaign=lemrock | H12: 26410 | I12: 147 | J12: =IF(H12=0,0,I12/H12)
A13: Boulanger | B13: Live | C13: Boulanger | D13: Printers/Copiers/Scanners/Fax | E13: Imprimantes et multifonctions au meilleur prix | Boulanger | F13: La cartouche d’encre Canon CLI-551 XL Cyan joue la haute capacité pour des impressions durables, à retrouver avec les imprimantes Boulanger. | G13: https://www.boulanger.com/ref/142796?at_medium=gea&at_campaign=lemrock | H13: 24922 | I13: 152 | J13: =IF(H13=0,0,I13/H13)
... A2174: Comptoir des Pros | B2174: Hors fichier de suivi | C2174: MABEX | D2174: Sanitaire et salle de bain | E2174: Sèche-serviettes Thermor prix bas | Comptoir des Pros | F2174: Sèche-serviettes électriques Thermor pour chauffer la salle de bain et sécher le linge : la gamme du fabricant français au prix pro, avec les conseils de nos experts. | G2174: https://www.comptoirdespros.com/marques/thermor/seche-serviette-thermor.html | H2174: 1249 | I2174: 8 | J2174: =IF(H2174=0,0,I2174/H2174)

Sheet Top 10 ads par client
A1: Top 10 des ads les plus diffusées par client — septembre 2026
A2: Classées par impressions. Le détail complet (toutes les ads) est dans l'onglet « Détail par ad ».
A4: # | B4: Titre de l'ad | C4: Campagne | D4: Impressions | E4: Clics | F4: CTR
A5: Boulanger · Live
A6: 1 | B6: Barre de son BOSE TV Speaker | C6: Boulanger | D6: 52227 | E6: 147 | F6: =IF(D6=0,0,E6/D6)
A7: 2 | B7: Smartphone SAMSUNG Galaxy S24 Ultra Gris | C7: Boulanger | D7: 42500 | E7: 217 | F7: =IF(D7=0,0,E7/D7)
A8: 3 | B8: Console Portable ASUS Rog Xbox Ally | C8: Boulanger | D8: 40605 | E8: 1390 | F8: =IF(D8=0,0,E8/D8)
A9: 4 | B9: Console NINTENDO Switch 2 | C9: Boulanger | D9: 39174 | E9: 346 | F9: =IF(D9=0,0,E9/D9)
A10: 5 | B10: Informatique, son et téléphonie prix bas | Boulanger | C10: Boulanger | D10: 38962 | E10: 373 | F10: =IF(D10=0,0,E10/D10)
A11: 6 | B11: High-tech et électroménager au meilleur prix | Boulanger | C11: Boulanger | D11: 29388 | E11: 186 | F11: =IF(D11=0,0,E11/D11)
A12: 7 | B12: Clavier+Souris LOGITECH MK330 | C12: Boulanger | D12: 28415 | E12: 210 | F12: =IF(D12=0,0,E12/D12)
A13: 8 | B13: Ecran ASUS ZENSCREEN MB16AWP Portable 16 | C13: Boulanger | D13: 28172 | E13: 157 | F13: =IF(D13=0,0,E13/D13)
A14: 9 | B14: GPS vélo GARMIN Edge Explore 2 - support potence | C14: Boulanger | D14: 26642 | E14: 125 | F14: =IF(D14=0,0,E14/D14)
A15: 10 | B15: GPS TOMTOM GO CLASSIC 5'' EU nouvelle génération | C15: Boulanger | D15: 26461 | E15: 70 | F15: =IF(D15=0,0,E15/D15)
A17: Cdiscount Voyages · Live
A18: 1 | B18: Cdiscount Voyages - destinations tendances à prix bas | C18: Cdiscount vol paiement 4x | D18: 139280 | E18: 779 | F18: =IF(D18=0,0,E18/D18)
A19: 2 | B19: Cdiscount Voyages - vols courts-courriers Europe | C19: Cdiscount vol paiement 4x | D19: 135342 | E19: 655 | F19: =IF(D19=0,0,E19/D19)
A20: 3 | B20: Cdiscount Voyages - vols vers le Moyen-Orient et l’Islande | C20: Cdiscount vol paiement 4x | D20: 134684 | E20: 684 | F20: =IF(D20=0,0,E20/D20)
A21: 4 | B21: Cdiscount Voyages - vols vers l’Afrique à prix bas | C21: Cdiscount vol paiement 4x | D21: 134272 | E21: 693 | F21: =IF(D21=0,0,E21/D21)
A22: 5 | B22: Cdiscount Voyages - vols vers Thaïlande, Vietnam, Bali | C22: Cdiscount vol paiement 4x | D22: 134173 | E22: 698 | F22: =IF(D22=0,0,E22/D22)
A23: 6 | B23: Cdiscount Voyages - vols vers la Martinique et la Guadeloupe | C23: Cdiscount vol paiement 4x | D23: 133477 | E23: 676 | F23: =IF(D23=0,0,E23/D23)
A24: 7 | B24: Séjours tout compris pas chers | Cdiscount Voyages | C24: cdiscount voyage séjours 4 | D24: 26453 | E24: 138 | F24: =IF(D24=0,0,E24/D24)
A25: 8 | B25: Séjour pas cher - Paiement en 4x - 🌍 Cdiscount Voyages | C25: cdiscount voyage séjours 4 | D25: 23600 | E25: 100 | F25: =IF(D25=0,0,E25/D25)
A26: 9 | B26: Vacances et séjours au meilleur prix | Cdiscount Voyages | C26: cdiscount voyage séjours 4 | D26: 21529 | E26: 123 | F26: =IF(D26=0,0,E26/D26)
A27: 10 | B27: Hôtel Amber El Fell 4* | C27: cdiscount voyage séjours 4 | D27: 20798 | E27: 100 | F27: =IF(D27=0,0,E27/D27)
A29: Monoprix · Live
A30: 1 | B30: Boxers, slips et lingerie prix bas | Monoprix | C30: Monoprix Mode 2 | D30: 65997 | E30: 271 | F30: =IF(D30=0,0,E30/D30)
A31: 2 | B31: Bonduelle mâche & roquette sachet de 100g | C31: Monoprix Courses | D31: 49182 | E31: 101 | F31: =IF(D31=0,0,E31/D31)
A32: 3 | B32: Monoprix - Parapharmacie et premiers soins | C32: Monoprix Courses | D32: 36915 | E32: 125 | F32: =IF(D32=0,0,E32/D32)
A33: 4 | B33: Fruits frais pas chers | Monoprix | C33: Monoprix Courses | D33: 34081 | E33: 90 | F33: =IF(D33=0,0,E33/D33)
A34: 5 | B34: Parapharmacie et premiers soins prix bas | Monoprix | C34: Monoprix Courses | D34: 32509 | E34: 101 | F34: =IF(D34=0,0,E34/D34)
A35: 6 | B35: côte de veau sans os 2x | C35: Monoprix Courses | D35: 32183 | E35: 92 | F35: =IF(D35=0,0,E35/D35)
A36: 7 | B36: Yarden choucroute nature 900g | C36: Monoprix Courses | D36: 27519 | E36: 80 | F36: =IF(D36=0,0,E36/D36)
A37: 8 | B37: Épicerie et produits frais au meilleur prix | Monoprix | C37: Monoprix Courses | D37: 26654 | E37: 90 | F37: =IF(D37=0,0,E37/D37)
A38: 9 | B38: Le gaulois saucisses de volaille x6 300g | C38: Monoprix Courses | D38: 25848 | E38: 72 | F38: =IF(D38=0,0,E38/D38)
A39: 10 | B39: côte de porc x2 260g | C39: Monoprix Courses | D39: 24095 | E39: 71 | F39: =IF(D39=0,0,E39/D39)
A41: Cdiscount Mobile · Live
A42: 1 | B42: Forfait 40 Go - Sans Engagement - Cdiscount Mobile | C42: Cdiscount - Mobile 3 | D42: 604607 | E42: 3190 | F42: =IF(D42=0,0,E42/D42)
A43: 2 | B43: Forfait 150 Go - Sans Engagement - Cdiscount Mobile | C43: Cdiscount - Mobile 3 | D43: 594115 | E43: 3055 | F43: =IF(D43=0,0,E43/D43)
A44: 3 | B44: Forfait 40 Go - Sans Engagement - Cdiscount Mobile | C44: Cdiscount - Mobile 3 | D44: 562222 | E44: 2893 | F44: =IF(D44=0,0,E44/D44)
...

Sheet Méthodo
A1: Méthodologie
A2: Période : 1er au 30 septembre 2026, jours en UTC.
A3: Périmètre : ventes directes uniquement (annonces des campagnes Lemrock). Teads, programmatique et annonces « filler » non vendues sont exclus.
A4: Impression : ad entrée dans le viewport (pixel), dédupliquée une fois par ad sur 24 h.
A5: Clic : clic sur l'ad via la redirection Lemrock, dédupliqué une fois par ad sur 24 h.
A6: CTR = clics / impressions.
A7: « Ad » = une annonce de la plateforme (titre, description, URL). Les clients en catalogue produits ont une ad par produit, d'où des centaines d'ads.
A8: Les ads avec peu d'impressions ont un CTR peu significatif : privilégier l'onglet Top 10.
A9: Correspondance des noms : les noms plateforme sont alignés sur le fichier « Suivi Campagnes & Clients v11 » (ex. Cdiscount Vols → Cdiscount Voyages, Sécurité routière → DSR, Pierre & Vacances → PV).
A10: Statut repris de l'onglet « Suivi Client » du fichier de suivi.
A11: Source : BigQuery lemrock-prod (fct_ad_impressions, fct_ad_clicks, events.*_v2 pour l'identifiant d'ad, postgres.ad). Totaux par client rapprochés de fea_campaign_daily_metrics. Extraction du 12/10/2026.
